<?xml version="1.0"?>
<robot name="myfirst">
  <link name="base_link">
    <visual>
      <geometry>
        <cylinder length="1.04775" radius="0.2032"/>
      </geometry>
	<material name="clear">
		<color rgba="0.75 0.75 0.75 0.4"/>
	</material>
    </visual>
  </link>

  <link name="base_lower_link">
    <visual>
      <geometry>
        <box size="0.41148 0.30988 0.05588"/> 
      </geometry>
      <material name="grey">
	<color rgba="0.5 0.5 0.5 1"/>
      </material>
    </visual>
  </link>

  <joint name="center_joint" type="continuous">
    <axis xyz="0 0 1"/>
    <parent link="base_link"/>
    <child link="base_lower_link"/>
    <origin rpy="0 0 0" xyz="0 0 -0.551815"/>
  </joint>

  <link name="hitch_front_link">
    <visual>
      <geometry>
        <cylinder length="0.1524" radius="0.01"/>
      </geometry>
      <material name="silver">
	<color rgba="0.75 0.75 0.75 1"/>
      </material>
    </visual>
  </link>

  <joint name="hitch_joint" type="fixed">
    <axis xyz="0 0 1"/>
    <parent link="base_lower_link"/>
    <child link="hitch_front_link"/>
    <origin rpy="0 0 0" xyz="0.18 0 0.0762"/>
  </joint>

  <link name="wheel_front_left">
    <visual>
      <geometry>
        <cylinder length="0.0508" radius="0.0762"/>
      </geometry>
      <material name="black">
        <color rgba="0 0 0 1"/>
      </material>
    </visual>
  </link>

  <joint name="axiz_front_left" type="continuous">
    <axis xyz="0 0 1"/>
    <parent link="base_lower_link"/>
    <child link="wheel_front_left"/>
    <origin rpy="-1.5708 0 0" xyz="0.165862 0.18034 0"/>
  </joint>

 <link name="wheel_front_right">
    <visual>
      <geometry>
        <cylinder length="0.0508" radius="0.0762"/>
      </geometry>
      <material name="black"/>
    </visual>
  </link>

  <joint name="axiz_front_right" type="continuous">
    <axis xyz="0 0 1"/>
    <parent link="base_lower_link"/>
    <child link="wheel_front_right"/>
    <origin rpy="-1.5708 0 0" xyz="0.165862 -0.18034 0"/>
  </joint>

  <link name="wheel_rear_right">
    <visual>
      <geometry>
        <cylinder length="0.0508" radius="0.0762"/>
      </geometry>
      <material name="black"/>
    </visual>
  </link>

  <joint name="axiz_rear_right" type="continuous">
    <axis xyz="0 0 1"/>
    <parent link="base_lower_link"/>
    <child link="wheel_rear_right"/>
    <origin rpy="-1.5708 0 0" xyz="-0.165862 -0.18034 0"/>
  </joint>

  <link name="wheel_rear_left">
    <visual>
      <geometry>
        <cylinder length="0.0508" radius="0.0762"/>
      </geometry>
      <material name="black"/>
    </visual>
  </link>

  <joint name="axiz_rear_left" type="continuous">
    <axis xyz="0 0 1"/>
    <parent link="base_lower_link"/>
    <child link="wheel_rear_left"/>
    <origin rpy="-1.5708 0 0" xyz="-0.165862 0.18034 0"/>
  </joint>
</robot>


